Workbook

Sheet Tổng quan
B1: TECHSTORE – KẾ HOẠCH & PHÂN CÔNG DỰ ÁN (4 NGÀY)
B2: Đồ án nhóm – Topic 1: RESTful API · PHP thuần, MySQL, HTML/CSS/JS
B3: Ô nền vàng = ô cần nhập/sửa. Chữ xanh dương = số liệu đầu vào. Mọi số tổng hợp tự tính theo sheet 'Phân công'.
B4: Tên dự án | C4: TechStore – Website TMĐT đồ công nghệ
B5: Ngày bắt đầu (Day 1) | C5: 46316
B6: Ngày kết thúc (Day 4) | C6: =C5+3 -> 46319
B7: Mô hình làm việc | C7: Git Flow rút gọn · Stand-up 08:30 mỗi ngày · PR + review bắt buộc
B8: Repo Git | C8: https://github.com/trannam1304/TechStore
B9: Tài liệu | C9: Readme.md · GIT_WORKFLOW.md · Checklist nộp bài · docs/openapi.yaml
B11: ĐỘI NGŨ
B12: Mã | C12: Họ tên | D12: Vai trò | E12: Trọng tâm công việc
B13: A | C13: Hữu Nam | D13: Leader / Tech Lead / Back-end Core | E13: Kiến trúc, Auth/JWT, Giỏ hàng, Đơn hàng, QR, quản lý repo, tích hợp, Chương 3 & 6, ghép báo cáo Word/PDF, đóng gói nộp bài
B14: B | C14: Thành Trung | D14: Back-end & Thuật toán | E14: CSDL, Sản phẩm, Admin API, Gợi ý sản phẩm, Chương 2 & 4, dọn mã nguồn, Readme, dựng video
B15: C | C15: Kiệt | D15: Front-end | E15: Toàn bộ giao diện khách + admin, khung báo cáo theo template, Mở đầu + Chương 1 & 5, slide, demo giao diện, chạy thử trên máy sạch
B17: TIẾN ĐỘ & KHỐI LƯỢNG (tự tính)
B18: Thành viên | C18: Số nhiệm vụ | D18: Tổng giờ ước tính | E18: Số việc hoàn thành | F18: % tiến độ (theo giờ)
B19: =C13 -> Hữu Nam | C19: =COUNTIF('Phân công'!$G$2:$G$121,"Hữu Nam") -> 26 | D19: =SUMIF('Phân công'!$G$2:$G$121,"Hữu Nam",'Phân công'!$J$2:$J$121) -> 34 | E19: =COUNTIFS('Phân công'!$G$2:$G$121,"Hữu Nam",'Phân công'!$M$2:$M$121,"Hoàn thành") -> 3 | F19: =IFERROR(SUMPRODUCT(('Phân công'!$G$2:$G$121="Hữu Nam")*'Phân công'!$J$2:$J$121*'Phân công'!$N$2:$N$121)/D19,0) -> 0
B20: =C14 -> Thành Trung | C20: =COUNTIF('Phân công'!$G$2:$G$121,"Thành Trung") -> 25 | D20: =SUMIF('Phân công'!$G$2:$G$121,"Thành Trung",'Phân công'!$J$2:$J$121) -> 35 | E20: =COUNTIFS('Phân công'!$G$2:$G$121,"Thành Trung",'Phân công'!$M$2:$M$121,"Hoàn thành") -> 0 | F20: =IFERROR(SUMPRODUCT(('Phân công'!$G$2:$G$121="Thành Trung")*'Phân công'!$J$2:$J$121*'Phân công'!$N$2:$N$121)/D20,0) -> 0
B21: =C15 -> Kiệt | C21: =COUNTIF('Phân công'!$G$2:$G$121,"Kiệt") -> 23 | D21: =SUMIF('Phân công'!$G$2:$G$121,"Kiệt",'Phân công'!$J$2:$J$121) -> 33.5 | E21: =COUNTIFS('Phân công'!$G$2:$G$121,"Kiệt",'Phân công'!$M$2:$M$121,"Hoàn thành") -> 0 | F21: =IFERROR(SUMPRODUCT(('Phân công'!$G$2:$G$121="Kiệt")*'Phân công'!$J$2:$J$121*'Phân công'!$N$2:$N$121)/D21,0) -> 0
B22: TỔNG CỘNG | C22: =SUM(C19:C21) -> 74 | D22: =SUM(D19:D21) -> 102.5 | E22: =SUM(E19:E21) -> 3 | F22: =IFERROR(SUMPRODUCT('Phân công'!$J$2:$J$121*'Phân công'!$N$2:$N$121)/D22,0) -> 0
B24: THỐNG KÊ TRẠNG THÁI
B25: Chưa bắt đầu | C25: =COUNTIF('Phân công'!$M$2:$M$121,B25) -> 71
B26: Đang làm | C26: =COUNTIF('Phân công'!$M$2:$M$121,B26) -> 0
B27: Đang review | C27: =COUNTIF('Phân công'!$M$2:$M$121,B27) -> 0
B28: Hoàn thành | C28: =COUNTIF('Phân công'!$M$2:$M$121,B28) -> 3
B29: Bị chặn | C29: =COUNTIF('Phân công'!$M$2:$M$121,B29) -> 0
B31: Giả định: bắt đầu 21/10/2026 và làm 4 ngày liên tục (đổi ô C5 nếu khác). Giữ nguyên toàn bộ 70 đầu việc của bản 8 ngày + thêm 4 việc bám đề bài (T71–T74). Kế hoạch dựa trên vibe coding: AI sinh phần lớn code nên số giờ mỗi việc được nén còn khoảng 45–60% (báo cáo, kiểm thử, video nén ít hơn); khối lượng ~8,5 giờ/người/ngày, đỉnh ~9–9,5 giờ. Giờ là ước tính của leader, chỉnh lại sau kickoff.
B33: TÌNH TRẠNG BÀI NỘP (tự tính)
B34: Checklist nộp bài (đạt / tổng) | C34: ='Checklist nộp bài'!C3 -> 0 / 28 | D34: ='Checklist nộp bài'!D3 -> 0
B35: Số trang thân báo cáo (mục tiêu 20–60) | C35: ='Báo cáo'!C3 -> 40 | D35: ='Báo cáo'!D3 -> ĐẠT (20–60 trang)
B36: Thời lượng video (tối đa 20 phút) | C36: =Video!C3 -> 18 | D36: =Video!D3 -> ĐẠT (≤ 20 phút)

Sheet Checklist nộp bài
A1: CHECKLIST NỘP BÀI – 4 HẠNG MỤC BẮT BUỘC
A2: Chọn trạng thái ở cột G. Chỉ nộp khi mọi mục đều 'Đạt'. Hạn = ngày thứ trong kế hoạch 4 ngày.
B3: Đã đạt | C3: =COUNTIF(G5:G32,"Đạt")&" / "&COUNT(A5:A32) -> 0 / 28 | D3: =IFERROR(COUNTIF(G5:G32,"Đạt")/COUNT(A5:A32),0) -> 0
A4: # | B4: Hạng mục | C4: Yêu cầu bắt buộc | D4: Cách kiểm tra | E4: Phụ trách | F4: Hạn (ngày thứ) | G4: Trạng thái
A5: 1 | B5: 1. Báo cáo (Report) | C5: Nộp đủ cả 2 định dạng: Word (.docx) và PDF | D5: Có 2 file cùng nội dung, mở được trên máy khác | E5: Hữu Nam | F5: 4 | G5: Chưa kiểm
A6: 2 | B6: 1. Báo cáo (Report) | C6: Bám sát template của Khoa (font, cỡ chữ, lề, giãn dòng, đánh số chương/mục, thứ tự các phần) | D6: Đối chiếu từng trang với template; kiểm tra bởi Kiệt + Hữu Nam | E6: Kiệt | F6: 4 | G6: Chưa kiểm
A7: 3 | B7: 1. Báo cáo (Report) | C7: Độ dài phần thân 20–60 trang (không tính trang bìa và phụ lục) | D7: Xem ô tổng trang ở sheet 'Báo cáo'; đếm lại trên file Word/PDF cuối | E7: Hữu Nam | F7: 4 | G7: Chưa kiểm
A8: 4 | B8: 1. Báo cáo (Report) | C8: Trang bìa: logo đúng (file logo chính thức của trường/Khoa) | D8: Đối chiếu với template + website trường | E8: Hữu Nam | F8: 4 | G8: Chưa kiểm
A9: 5 | B9: 1. Báo cáo (Report) | C9: Trang bìa: tên giảng viên đúng (chính tả, học hàm/học vị) | D9: Đối chiếu với thông tin GV xác nhận ở sheet 'Thông tin bìa' | E9: Hữu Nam | F9: 4 | G9: Chưa kiểm
A10: 6 | B10: 1. Báo cáo (Report) | C10: Trang bìa: đủ và đúng họ tên + MSSV của 3 thành viên (Hữu Nam, Kiệt, Thành Trung), tên đề tài, lớp, học kỳ | D10: Từng thành viên tự kiểm tra thông tin của mình | E10: Hữu Nam | F10: 4 | G10: Chưa kiểm
A11: 7 | B11: 1. Báo cáo (Report) | C11: Trang bìa đã được ít nhất 2 người kiểm tra chéo trên CẢ bản Word và bản PDF | D11: Ghi tên 2 người kiểm tra ở sheet 'Thông tin bìa' | E11: Kiệt | F11: 4 | G11: Chưa kiểm
A12: 8 | B12: 1. Báo cáo (Report) | C12: Trình bày chuyên nghiệp: mục lục tự động, số trang, hình/bảng có số và chú thích, trích dẫn nguồn, font thống nhất, không lỗi chính tả | D12: Đọc soát toàn văn; cập nhật mục lục (F9) trước khi xuất PDF | E12: Kiệt | F12: 4 | G12: Chưa kiểm
A13: 9 | B13: 1. Báo cáo (Report) | C13: PDF xuất từ Word: không lỗi font/ảnh, số trang và nội dung khớp bản Word | D13: Mở PDF, lật toàn bộ trang | E13: Hữu Nam | F13: 4 | G13: Chưa kiểm
A14: 10 | B14: 2. Mã nguồn | C14: Mã nguồn sạch: không file rác/debug/backup/log, không lộ mật khẩu hay khóa thật | D14: Quét thư mục; kiểm tra .gitignore và .env | E14: Thành Trung | F14: 4 | G14: Chưa kiểm
A15: 11 | B15: 2. Mã nguồn | C15: Thư mục tổ chức gọn gàng (public/, api/, config/, database/, docs/, tests/) | D15: So khớp cấu trúc trong README | E15: Thành Trung | F15: 4 | G15: Chưa kiểm
A16: 12 | B16: 2. Mã nguồn | C16: Có file quản lý thư viện/dependencies cần thiết (composer.json + composer.lock, hoặc ghi rõ không dùng thư viện ngoài; thư viện JS đặt sẵn trong public/assets/vendor) | D16: Chạy cài đặt trên thư mục sạch | E16: Thành Trung | F16: 3 | G16: Chưa kiểm
... A32: 28 | B32: 4. Readme.md | C32: Giáo viên có thể tự khởi chạy code chỉ bằng Readme (đã xác nhận trên máy sạch) | D32: Kiệt xác nhận | E32: Kiệt | F32: 4 | G32: Chưa kiểm

Sheet Phân công
A1: ID | B1: Ngày thứ | C1: Ngày | D1: Nhóm việc | E1: Nhiệm vụ | F1: Sản phẩm bàn giao | G1: Phụ trách | H1: Review | I1: Ưu tiên | J1: Giờ ước tính | K1: Phụ thuộc | L1: Nhánh Git | M1: Trạng thái | N1: % hoàn thành | O1: Ghi chú
A2: T01 | B2: 1 | C2: ='Tổng quan'!$C$5+B2-1 -> 46316 | D2: Quản lý | E2: Tạo repo GitHub (private), bảo vệ nhánh main, tạo nhánh develop, mời thành viên, bật GitHub Projects (Kanban) + labels | F2: Repo + branch rules + board (xem GIT_WORKFLOW.md) | G2: Hữu Nam | H2: Thành Trung | I2: Cao | J2: 1 | K2: - | L2: main / develop | M2: Hoàn thành | N2: 0 | O2: Nhờ AI viết GIT_WORKFLOW.md ngắn (1 trang)
A3: T02 | B3: 1 | C3: ='Tổng quan'!$C$5+B3-1 -> 46316 | D3: Quản lý | E3: Họp kickoff: chốt phạm vi, backlog, quy ước code & API, lịch stand-up; nhận template báo cáo của Khoa; xác nhận với giảng viên thông tin trang bìa (logo, tên GV, thành viên) | F3: Biên bản họp docs/meeting-notes.md + sheet 'Thông tin bìa' đã điền và xác nhận | G3: Hữu Nam | H3: Thành Trung | I3: Cao | J3: 1 | K3: - | L3: docs/kickoff | M3: Hoàn thành | N3: 0 | O3: Soạn CONTEXT.md (stack, quy ước, định dạng JSON) – dán vào mọi prompt AI. Đối chiếu đề bài: sheet 'Đối chiếu đề bài'
A4: T03 | B4: 1 | C4: ='Tổng quan'!$C$5+B4-1 -> 46316 | D4: Hạ tầng | E4: Dựng khung dự án: cấu trúc thư mục, front controller, Router, Response helper, config/.env, autoload, route /api/v1/ping | F4: Khung chạy được trên local | G4: Hữu Nam | H4: Thành Trung | I4: Cao | J4: 2 | K4: T01 | L4: feature/project-skeleton | M4: Hoàn thành | N4: 0 | O4: Prompt: dán CONTEXT.md + 'tạo khung PHP thuần theo MVC, không dùng framework'
A5: T04 | B5: 1 | C5: ='Tổng quan'!$C$5+B5-1 -> 46316 | D5: Database | E5: Thiết kế ERD và viết schema.sql (≥15 bảng: users, products, categories, brands, product_images, product_specs, carts, orders, order_items, payments, reviews, wishlists, coupons, refresh_tokens, product_views, product_similarity, audit_logs) | F5: docs/erd.png + database/schema.sql | G5: Thành Trung | H5: Hữu Nam | I5: Cao | J5: 2 | K5: T02 | L5: feature/database-schema | M5: Chưa bắt đầu | N5: 0
A6: T05 | B6: 1 | C6: ='Tổng quan'!$C$5+B6-1 -> 46316 | D6: Database | E6: Viết seed.sql: ≥40 sản phẩm, 8 hãng, 5 danh mục, user mẫu, ~30 đơn mẫu (phục vụ thuật toán gợi ý) | F6: database/seed.sql | G6: Thành Trung | H6: Hữu Nam | I6: Cao | J6: 1 | K6: T04 | L6: feature/database-schema | M6: Chưa bắt đầu | N6: 0
A7: T06 | B7: 1 | C7: ='Tổng quan'!$C$5+B7-1 -> 46316 | D7: Tài liệu | E7: Viết khung openapi.yaml (hợp đồng API giữa FE và BE) cho các nhóm Auth, Product, Cart, Order | F7: docs/openapi.yaml v0.1 | G7: Thành Trung | H7: Hữu Nam | I7: Cao | J7: 1 | K7: T02 | L7: docs/openapi | M7: Chưa bắt đầu | N7: 0
A8: T07 | B8: 1 | C8: ='Tổng quan'!$C$5+B8-1 -> 46316 | D8: Thiết kế | E8: Wireframe + UI kit: trang chủ, danh sách, chi tiết, giỏ, checkout, trang QR, admin; chọn màu/font/spacing (design tokens CSS) | F8: docs/wireframes + assets/css/tokens.css | G8: Kiệt | H8: Hữu Nam | I8: Cao | J8: 2 | K8: T02 | L8: feature/ui-kit | M8: Chưa bắt đầu | N8: 0
A9: T08 | B9: 1 | C9: ='Tổng quan'!$C$5+B9-1 -> 46316 | D9: Hạ tầng | E9: Cài môi trường (XAMPP/Laragon, PHP 8, MySQL, Postman), clone repo, chạy thử khung | F9: Cả nhóm chạy được local | G9: Kiệt | H9: Hữu Nam | I9: Cao | J9: 0.5 | K9: T01 | L9: - | M9: Chưa bắt đầu | N9: 0
A10: T09 | B10: 1 | C10: ='Tổng quan'!$C$5+B10-1 -> 46316 | D10: Báo cáo | E10: Nhận template báo cáo của Khoa, dựng khung .docx đúng template (styles, mục lục tự động, đánh số trang, trang bìa); lập dàn ý chương và phân bổ số trang (20–60 trang, không tính bìa & phụ lục) – xem sheet 'Báo cáo' | F10: Khung báo cáo .docx đúng template + dàn ý | G10: Kiệt | H10: Hữu Nam | I10: Cao | J10: 1.5 | K10: T02 | L10: docs/report | M10: Chưa bắt đầu | N10: 0
A11: T10 | B11: 1 | C11: ='Tổng quan'!$C$5+B11-1 -> 46316 | D11: Auth | E11: JwtService (HS256 ký/xác thực, exp), AuthMiddleware, RoleMiddleware (customer/admin) | F11: api/services/JwtService.php + middleware | G11: Hữu Nam | H11: Thành Trung | I11: Cao | J11: 1.5 | K11: T03 | L11: feature/auth-jwt | M11: Chưa bắt đầu | N11: 0 | O11: Đề bài: bảo mật bằng JWT. Tự đọc hiểu JwtService để giải thích trong video
A12: T11 | B12: 1 | C12: ='Tổng quan'!$C$5+B12-1 -> 46316 | D12: Auth | E12: Endpoint register / login / refresh / logout / me; password_hash; refresh token lưu DB | F12: /auth/* chạy được qua Postman | G12: Hữu Nam | H12: Thành Trung | I12: Cao | J12: 1.5 | K12: T10, T04 | L12: feature/auth-jwt | M12: Chưa bắt đầu | N12: 0 | O12: Đề bài: JWT + refresh token
A13: T12 | B13: 1 | C13: ='Tổng quan'!$C$5+B13-1 -> 46316 | D13: Hạ tầng | E13: Validator, ErrorHandler chuẩn JSON, CORS config | F13: helpers + middleware | G13: Hữu Nam | H13: Thành Trung | I13: TB | J13: 0.5 | K13: T03 | L13: feature/auth-jwt | M13: Chưa bắt đầu | N13: 0
A14: T13 | B14: 1 | C14: ='Tổng quan'!$C$5+B14-1 -> 46316 | D14: Sản phẩm | E14: GET /products: lọc (hãng, giá, danh mục, RAM/ROM), sắp xếp, tìm kiếm từ khóa, phân trang | F14: API danh sách sản phẩm | G14: Thành Trung | H14: Hữu Nam | I14: Cao | J14: 2 | K14: T05, T03 | L14: feature/product-api | M14: Chưa bắt đầu | N14: 0 | O14: Đề bài: API quản lý dataset (kho sản phẩm) – lọc/tìm/phân trang
A15: T14 | B15: 1 | C15: ='Tổng quan'!$C$5+B15-1 -> 46316 | D15: Sản phẩm | E15: GET /products/{id} (ảnh, thông số, đánh giá tóm tắt) + API categories, brands | F15: API chi tiết + danh mục + hãng | G15: Thành Trung | H15: Hữu Nam | I15: Cao | J15: 1 | K15: T13 | L15: feature/product-api | M15: Chưa bắt đầu | N15: 0
A16: T15 | B16: 1 | C16: ='Tổng quan'!$C$5+B16-1 -> 46316 | D16: Test | E16: Tạo Postman collection + environment (Auth, Products), script test tự động | F16: tests/postman_collection.json | G16: Thành Trung | H16: Hữu Nam | I16: TB | J16: 1 | K16: T11, T13 | L16: feature/product-api | M16: Chưa bắt đầu | N16: 0 | O16: Đề bài: dùng Postman để gọi API
A17: T16 | B17: 1 | C17: ='Tổng quan'!$C$5+B17-1 -> 46316 | D17: Front-end | E17: Layout chung (header/footer/menu/ô tìm kiếm), CSS base responsive, api.js (fetch wrapper, gắn JWT, xử lý 401/refresh) | F17: assets/css/base.css, assets/js/api.js | G17: Kiệt | H17: Hữu Nam | I17: Cao | J17: 2 | K17: T07 | L17: feature/fe-layout | M17: Chưa bắt đầu | N17: 0 | O17: Đề bài: dùng front-end để gọi API. Dán openapi.yaml vào prompt cho AI
A18: T17 | B18: 1 | C18: ='Tổng quan'!$C$5+B18-1 -> 46316 | D18: Front-end | E18: Trang đăng nhập / đăng ký (validate form, lưu token an toàn) | F18: pages/login.html, register.html | G18: Kiệt | H18: Hữu Nam | I18: Cao | J18: 1 | K18: T11, T16 | L18: feature/fe-auth | M18: Chưa bắt đầu | N18: 0
A19: T32 | B19: 1 | C19: ='Tổng quan'!$C$5+B19-1 -> 46316 | D19: Gợi ý | E19: Ghi nhận hành vi: bảng product_views + API POST /events/view (user hoặc session id) | F19: /events/view | G19: Hữu Nam | H19: Thành Trung | I19: Cao | J19: 0.5 | K19: T11 | L19: feature/recommendation | M19: Chưa bắt đầu | N19: 0
A20: T54 | B20: 1 | C20: ='Tổng quan'!$C$5+B20-1 -> 46316 | D20: Báo cáo | E20: Mở đầu & Chương 1: lý do chọn đề tài, mục tiêu, phạm vi, khảo sát mô hình CellphoneS, yêu cầu chức năng/phi chức năng, use case | F20: Mở đầu + Chương 1 (~6 trang) | G20: Kiệt | H20: Hữu Nam | I20: Cao | J20: 1.5 | K20: T09 | L20: docs/report | M20: Chưa bắt đầu | N20: 0
A21: T18 | B21: 2 | C21: ='Tổng quan'!$C$5+B21-1 -> 46317 | D21: Giỏ hàng | E21: Cart API: GET/POST/PUT/DELETE /cart, tính tổng tiền, kiểm tra tồn kho | F21: /cart chạy qua Postman | G21: Hữu Nam | H21: Thành Trung | I21: Cao | J21: 2 | K21: T11, T14 | L21: feature/cart-api | M21: Chưa bắt đầu | N21: 0
A22: T19 | B22: 2 | C22: ='Tổng quan'!$C$5+B22-1 -> 46317 | D22: Khuyến mãi | E22: Coupon API: kiểm tra mã (% hoặc số tiền, hạn dùng, giới hạn lượt) + áp dụng vào giỏ | F22: /coupons/validate | G22: Hữu Nam | H22: Thành Trung | I22: TB | J22: 1 | K22: T18 | L22: feature/coupon-api | M22: Chưa bắt đầu | N22: 0
A23: T20 | B23: 2 | C23: ='Tổng quan'!$C$5+B23-1 -> 46317 | D23: Test | E23: Cập nhật Postman: Cart, Coupon, Admin Product | F23: Collection v2 | G23: Thành Trung | H23: Hữu Nam | I23: TB | J23: 0.5 | K23: T18 | L23: feature/cart-api | M23: Chưa bắt đầu | N23: 0
A24: T21 | B24: 2 | C24: ='Tổng quan'!$C$5+B24-1 -> 46317 | D24: Admin | E24: Admin Product CRUD API (POST/PUT/PATCH/DELETE) + upload nhiều ảnh an toàn (kiểm tra mime, đổi tên file) | F24: /products (admin) | G24: Thành Trung | H24: Hữu Nam | I24: Cao | J24: 2 | K24: T13 | L24: feature/admin-product-api | M24: Chưa bắt đầu | N24: 0 | O24: Đề bài: CRUD đủ GET/POST/PUT/PATCH/DELETE
A25: T22 | B25: 2 | C25: ='Tổng quan'!$C$5+B25-1 -> 46317 | D25: Admin | E25: Admin Category / Brand CRUD API | F25: /categories, /brands (admin) | G25: Thành Trung | H25: Hữu Nam | I25: TB | J25: 1 | K25: T21 | L25: feature/admin-product-api | M25: Chưa bắt đầu | N25: 0
A26: T23 | B26: 2 | C26: ='Tổng quan'!$C$5+B26-1 -> 46317 | D26: Front-end | E26: Trang chủ: banner, danh mục, sản phẩm nổi bật / mới | F26: pages/index.html | G26: Kiệt | H26: Hữu Nam | I26: Cao | J26: 1.5 | K26: T16, T13 | L26: feature/fe-home | M26: Chưa bắt đầu | N26: 0
A27: T24 | B27: 2 | C27: ='Tổng quan'!$C$5+B27-1 -> 46317 | D27: Front-end | E27: Trang danh sách sản phẩm: bộ lọc, sắp xếp, phân trang, tìm kiếm gợi ý khi gõ (debounce) | F27: pages/products.html | G27: Kiệt | H27: Hữu Nam | I27: Cao | J27: 2 | K27: T13, T16 | L27: feature/fe-products | M27: Chưa bắt đầu | N27: 0
A28: T25 | B28: 2 | C28: ='Tổng quan'!$C$5+B28-1 -> 46317 | D28: Đơn hàng | E28: Order API: tạo đơn từ giỏ (transaction, trừ tồn kho), luồng trạng thái, hủy đơn, lịch sử đơn | F28: /orders | G28: Hữu Nam | H28: Thành Trung | I28: Cao | J28: 2 | K28: T18 | L28: feature/order-api | M28: Chưa bắt đầu | N28: 0 | O28: Dặn AI dùng transaction + kiểm tra chủ sở hữu đơn (chống IDOR)
A29: T26 | B29: 2 | C29: ='Tổng quan'!$C$5+B29-1 -> 46317 | D29: Thanh toán | E29: QrService (VietQR: số tiền + mã đơn), POST /payments/qr, trạng thái thanh toán, hết hạn QR | F29: /payments/qr | G29: Hữu Nam | H29: Thành Trung | I29: Cao | J29: 1.5 | K29: T25 | L29: feature/qr-payment | M29: Chưa bắt đầu | N29: 0
A30: T27 | B30: 2 | C30: ='Tổng quan'!$C$5+B30-1 -> 46317 | D30: Quản lý | E30: Review PR giữa tuần, merge develop, Checkpoint 1 (~50%): demo nội bộ luồng đăng nhập → giỏ → đặt hàng | F30: Biên bản checkpoint + develop ổn định | G30: Hữu Nam | H30: Thành Trung | I30: Cao | J30: 1 | K30: T25 | L30: develop | M30: Chưa bắt đầu | N30: 0 | O30: Cuối ngày 2; nếu trễ thì dồn việc ưu tiên TB/Thấp sang sau
A31: T28 | B31: 2 | C31: ='Tổng quan'!$C$5+B31-1 -> 46317 | D31: Đánh giá | E31: Review API (chỉ người đã mua, 1–5 sao) + Wishlist API | F31: /reviews, /wishlist | G31: Thành Trung | H31: Hữu Nam | I31: TB | J31: 1.5 | K31: T11, T14 | L31: feature/review-wishlist | M31: Chưa bắt đầu | N31: 0
A32: T29 | B32: 2 | C32: ='Tổng quan'!$C$5+B32-1 -> 46317 | D32: Admin | E32: Admin Order API (lọc, đổi trạng thái, xác nhận thanh toán) + User API (khóa/mở, đổi quyền) | F32: /admin/orders, /admin/users | G32: Thành Trung | H32: Hữu Nam | I32: Cao | J32: 2 | K32: T25 | L32: feature/admin-order-api | M32: Chưa bắt đầu | N32: 0
A33: T30 | B33: 2 | C33: ='Tổng quan'!$C$5+B33-1 -> 46317 | D33: Front-end | E33: Trang giỏ hàng: sửa số lượng, mã giảm giá, tổng tiền realtime | F33: pages/cart.html | G33: Kiệt | H33: Hữu Nam | I33: Cao | J33: 1.5 | K33: T18 | L33: feature/fe-cart | M33: Chưa bắt đầu | N33: 0
A34: T31 | B34: 2 | C34: ='Tổng quan'!$C$5+B34-1 -> 46317 | D34: Front-end | E34: Trang checkout (địa chỉ, phương thức thanh toán) + trang QR (hiển thị QR, đếm ngược, polling trạng thái) | F34: pages/checkout.html, payment-qr.html | G34: Kiệt | H34: Hữu Nam | I34: Cao | J34: 2 | K34: T25, T26 | L34: feature/fe-checkout | M34: Chưa bắt đầu | N34: 0
A35: T41 | B35: 2 | C35: ='Tổng quan'!$C$5+B35-1 -> 46317 | D35: Front-end | E35: Trang tài khoản: hồ sơ, địa chỉ, lịch sử đơn, hủy đơn, đánh giá, yêu thích | F35: pages/account.html | G35: Kiệt | H35: Hữu Nam | I35: Cao | J35: 1.5 | K35: T25, T28 | L35: feature/fe-account | M35: Chưa bắt đầu | N35: 0
A36: T46 | B36: 2 | C36: ='Tổng quan'!$C$5+B36-1 -> 46317 | D36: Báo cáo | E36: Chương 2: Cơ sở lý thuyết REST (nguyên tắc stateless, resource, uniform interface, cacheable, layered; HTTP methods GET/POST/PUT/PATCH/DELETE ↔ CRUD; safe/idempotent; status code) + bảng ví dụ request/response và bảng ánh xạ endpoint của TechStore | F36: Chương 2 (~7 trang) | G36: Thành Trung | H36: Hữu Nam | I36: Cao | J36: 1.5 | K36: T09 | L36: docs/report | M36: Chưa bắt đầu | N36: 0 | O36: Đề bài: nguyên tắc REST + HTTP methods ↔ CRUD. Bảng ánh xạ endpoint lấy từ T74
A37: T55 | B37: 2 | C37: ='Tổng quan'!$C$5+B37-1 -> 46317 | D37: Báo cáo | E37: Chương 3: Bảo mật API (JWT, OAuth 2.0 authorization code + PKCE, API key/Basic/session, HMAC webhook, OWASP API Top 10) + so sánh REST vs GraphQL vs SOAP kèm số liệu thực nghiệm (từ T72) | F37: Chương 3 (~7 trang) | G37: Hữu Nam | H37: Thành Trung | I37: Cao | J37: 2 | K37: T09 | L37: docs/report | M37: Chưa bắt đầu | N37: 0 | O37: Đề bài: bảo mật + so sánh. AI soạn nháp, tự sửa cho khớp code. Bổ sung số liệu thực nghiệm từ T72
A38: T73 | B38: 2 | C38: ='Tổng quan'!$C$5+B38-1 -> 46317 | D38: Test | E38: Postman folder 'Demo bảo mật' cho video: không token → 401; user thường gọi API admin → 403; token hết hạn → 401; refresh token; token sai chữ ký | F38: Folder Postman Demo bảo mật | G38: Thành Trung | H38: Hữu Nam | I38: Cao | J38: 0.5 | K38: T11, T15 | L38: feature/product-api | M38: Chưa bắt đầu | N38: 0 | O38: Đề bài: bảo mật API bằng JWT + gọi bằng Postman
A39: T33 | B39: 3 | C39: ='Tổng quan'!$C$5+B39-1 -> 46318 | D39: Admin | E39: Admin stats API: doanh thu theo ngày/tháng, top bán chạy, tồn kho thấp, đơn theo trạng thái | F39: /admin/stats | G39: Hữu Nam | H39: Thành Trung | I39: Cao | J39: 1.5 | K39: T25 | L39: feature/admin-stats | M39: Chưa bắt đầu | N39: 0
A40: T34 | B40: 3 | C40: ='Tổng quan'!$C$5+B40-1 -> 46318 | D40: Bảo mật | E40: Audit log (ghi hành động admin) + webhook giả lập xác nhận thanh toán QR (ký HMAC) | F40: /payments/webhook + bảng audit_logs | G40: Hữu Nam | H40: Thành Trung | I40: TB | J40: 1.5 | K40: T26 | L40: feature/payment-webhook | M40: Chưa bắt đầu | N40: 0 | O40: Đề bài: cơ chế xác thực khác (HMAC ký webhook)
...

Sheet Lịch 4 ngày
A1: Ngày thứ | B1: Ngày | C1: Mốc (Milestone) | D1: Giờ Hữu Nam | E1: Giờ Thành Trung | F1: Giờ Kiệt | G1: Tổng giờ | H1: Số việc | I1: Trọng tâm Hữu Nam | J1: Trọng tâm Thành Trung | K1: Trọng tâm Kiệt
A2: 1 | B2: ='Tổng quan'!$C$5+A2-1 -> 46316 | C2: Nền móng: repo, khung, DB, JWT/Auth, API sản phẩm, layout + đăng nhập FE, khung báo cáo, Mở đầu + Chương 1 | D2: =SUMIFS('Phân công'!$J$2:$J$121,'Phân công'!$B$2:$B$121,$A2,'Phân công'!$G$2:$G$121,"Hữu Nam") -> 8 | E2: =SUMIFS('Phân công'!$J$2:$J$121,'Phân công'!$B$2:$B$121,$A2,'Phân công'!$G$2:$G$121,"Thành Trung") -> 8 | F2: =SUMIFS('Phân công'!$J$2:$J$121,'Phân công'!$B$2:$B$121,$A2,'Phân công'!$G$2:$G$121,"Kiệt") -> 8.5 | G2: =SUM(D2:F2) -> 24.5 | H2: =COUNTIF('Phân công'!$B$2:$B$121,$A2) -> 19 | I2: Repo, khung, JWT/Auth, Validator/CORS, events/view | J2: ERD, schema, seed, openapi, API sản phẩm, Postman | K2: Wireframe, layout, api.js, login/register, khung báo cáo, Mở đầu + Ch1
A3: 2 | B3: ='Tổng quan'!$C$5+A3-1 -> 46317 | C3: Giỏ hàng, coupon, đơn hàng, QR, Admin API, review/wishlist + trang mua hàng; Chương 2 & 3 – Checkpoint 1 (~50%) | D3: =SUMIFS('Phân công'!$J$2:$J$121,'Phân công'!$B$2:$B$121,$A3,'Phân công'!$G$2:$G$121,"Hữu Nam") -> 9.5 | E3: =SUMIFS('Phân công'!$J$2:$J$121,'Phân công'!$B$2:$B$121,$A3,'Phân công'!$G$2:$G$121,"Thành Trung") -> 9 | F3: =SUMIFS('Phân công'!$J$2:$J$121,'Phân công'!$B$2:$B$121,$A3,'Phân công'!$G$2:$G$121,"Kiệt") -> 8.5 | G3: =SUM(D3:F3) -> 27 | H3: =COUNTIF('Phân công'!$B$2:$B$121,$A3) -> 18 | I3: Cart, Coupon, Order, QR, checkpoint, Chương 3 | J3: Admin Product/Category/Order/User API, Review/Wishlist, Postman, demo JWT, Chương 2 | K3: Trang chủ, danh sách, giỏ, checkout, QR, tài khoản
A4: 3 | B4: ='Tổng quan'!$C$5+A4-1 -> 46318 | C4: Gợi ý sản phẩm, Admin UI, OAuth + rate limit, REST nâng cao, so sánh REST/GraphQL, tích hợp – FEATURE FREEZE cuối ngày | D4: =SUMIFS('Phân công'!$J$2:$J$121,'Phân công'!$B$2:$B$121,$A4,'Phân công'!$G$2:$G$121,"Hữu Nam") -> 8.5 | E4: =SUMIFS('Phân công'!$J$2:$J$121,'Phân công'!$B$2:$B$121,$A4,'Phân công'!$G$2:$G$121,"Thành Trung") -> 9.5 | F4: =SUMIFS('Phân công'!$J$2:$J$121,'Phân công'!$B$2:$B$121,$A4,'Phân công'!$G$2:$G$121,"Kiệt") -> 8.5 | G4: =SUM(D4:F4) -> 26.5 | H4: =COUNTIF('Phân công'!$B$2:$B$121,$A4) -> 18 | I4: Stats, audit log, webhook HMAC, tích hợp E2E + OAuth, rà bảo mật, so sánh GraphQL, kịch bản video | J4: Content-based, mua cùng, cá nhân hóa, ETag/HATEOAS, chuẩn hóa thư viện, Chương 4 | K4: Admin dashboard/sản phẩm/đơn/người dùng, carousel gợi ý, Swagger UI + bảng ánh xạ
A5: 4 | B5: ='Tổng quan'!$C$5+A5-1 -> 46319 | C5: Test, sửa lỗi, code freeze, Chương 5–6, ghép báo cáo, quay + dựng video, đóng gói nộp bài | D5: =SUMIFS('Phân công'!$J$2:$J$121,'Phân công'!$B$2:$B$121,$A5,'Phân công'!$G$2:$G$121,"Hữu Nam") -> 8 | E5: =SUMIFS('Phân công'!$J$2:$J$121,'Phân công'!$B$2:$B$121,$A5,'Phân công'!$G$2:$G$121,"Thành Trung") -> 8.5 | F5: =SUMIFS('Phân công'!$J$2:$J$121,'Phân công'!$B$2:$B$121,$A5,'Phân công'!$G$2:$G$121,"Kiệt") -> 8 | G5: =SUM(D5:F5) -> 24.5 | H5: =COUNTIF('Phân công'!$B$2:$B$121,$A5) -> 19 | I5: OpenAPI v1.0, UAT, freeze/tag, Chương 6, ghép báo cáo, quay, nộp | J5: Test API, sửa bug BE, Readme, dọn source, quay + dựng video | K5: Test UI, sửa bug UI, máy sạch, Chương 5, slide, quay
C6: TỔNG | D6: =SUM(D2:D5) -> 34 | E6: =SUM(E2:E5) -> 35 | F6: =SUM(F2:F5) -> 33.5 | G6: =SUM(G2:G5) -> 102.5 | H6: =SUM(H2:H5) -> 74

Sheet Đối chiếu đề bài
A1: ĐỐI CHIẾU ĐỀ BÀI – REST (Topic 1)
A2: Mỗi yêu cầu của đề bài được gắn với việc cụ thể, chương báo cáo và đoạn video. Các dòng 'Khám phá thêm' là phần để lấy điểm cao hơn.
A4: # | B4: Yêu cầu đề bài | C4: Nhóm thực hiện | D4: Việc liên quan | E4: Chương báo cáo | F4: Video / Demo
A5: 1 | B5: Key point: REST principles (stateless, resource representation, uniform interface) | C5: Trình bày đủ 6 ràng buộc REST (thêm client-server, cacheable, layered, HATEOAS) và chỉ ra chỗ TechStore áp dụng | D5: T46, T71, T74 | E5: Chương 2 | F5: Phần 2 – Lý thuyết REST
A6: 2 | B6: Key point: HTTP methods GET/POST/PUT/DELETE ↔ CRUD | C6: Giải thích cả PATCH, safe/idempotent, status code; bảng ánh xạ 37 endpoint thật của dự án | D6: T46, T74, T21 | E6: Chương 2 + Phụ lục | F6: Phần 2 + Demo Postman
A7: 3 | B7: Key point: Security – JWT | C7: JWT HS256 có exp, refresh token lưu DB, phân quyền customer/admin; kịch bản 401/403 | D7: T10, T11, T55, T73, T51 | E7: Chương 3 | F7: Phần 3, Phần 5 (code Auth), Demo Postman
A8: 4 | B8: Key point: Security – OAuth | C8: Lý thuyết OAuth 2.0 (authorization code + PKCE) và demo đăng nhập Google | D8: T43, T55 | E8: Chương 3 | F8: Phần 3
A9: 5 | B9: Key point: Security – các phương thức xác thực khác | C9: So sánh Basic, API key, session cookie, JWT, OAuth 2.0; HMAC cho webhook thanh toán; OWASP API Top 10 | D9: T34, T51, T55 | E9: Chương 3 | F9: Phần 3
A10: 6 | B10: Key point: so sánh REST với GraphQL / SOAP | C10: Bảng so sánh lý thuyết + số liệu thực nghiệm (endpoint /graphql mini, ví dụ SOAP envelope) | D10: T55, T72 | E10: Chương 3 | F10: Phần 3
A11: 7 | B11: Demo: REST API quản lý dataset (kho/thư viện) | C11: Kho sản phẩm TechStore: CRUD sản phẩm, danh mục, hãng, tồn kho, giỏ hàng, đơn hàng | D11: T13, T14, T18, T21, T22, T25 | E11: Chương 4, 5 | F11: Phần 4, 5, 6 (kiến trúc, code)
A12: 8 | B12: Demo: bảo vệ API bằng JWT | C12: Endpoint admin chỉ cho role admin; endpoint khách cần token; tài khoản mẫu có sẵn trong Readme | D12: T10, T11, T12, T73 | E12: Chương 3, 5 | F12: Demo API với Postman
A13: 9 | B13: Demo: gọi API bằng front-end hoặc Postman | C13: Cả hai: giao diện khách + admin dùng fetch/api.js; Postman collection + folder Demo bảo mật | D13: T15, T16–T24, T44, T49, T73 | E13: Chương 5 | F13: Demo khách hàng, quản trị, Postman
A14: 10 | B14: Khám phá thêm: tài liệu hóa & thử API | C14: openapi.yaml + Swagger UI tại /docs | D14: T06, T44, T74 | E14: Chương 4, Phụ lục | F14: Phần Kiến trúc
A15: 11 | B15: Khám phá thêm: REST nâng cao | C15: ETag/Cache-Control, links kiểu HATEOAS, chuẩn lỗi RFC 7807, phiên bản /api/v1, rate limiting | D15: T71, T43 | E15: Chương 2, 4 | F15: Phần 2
A16: 12 | B16: Khám phá thêm: tính năng thực tế | C16: Thanh toán QR, gợi ý sản phẩm (content-based + co-occurrence), thống kê admin | D16: T26, T35, T36, T39, T33 | E16: Chương 4 | F16: Phần Giải thích code, Demo

Sheet Báo cáo
A1: BÁO CÁO – PHÂN BỔ SỐ TRANG & TIẾN ĐỘ (Word + PDF)
A2: Yêu cầu: 20–60 trang, không tính trang bìa và phụ lục. Chỉnh số chương/mục theo template của Khoa. Ô xanh dương = số trang mục tiêu, có thể sửa.
B3: Tổng số trang phần thân (tính vào 20–60) | C3: =SUMIF(F6:F16,"Có",E6:E16) -> 40 | D3: =IF(AND(C3>=20,C3<=60),"ĐẠT (20–60 trang)","CHƯA ĐẠT – điều chỉnh số trang") -> ĐẠT (20–60 trang)
A5: # | B5: Phần / Chương | C5: Nội dung chính | D5: Phụ trách | E5: Số trang mục tiêu | F5: Tính vào 20–60 trang? | G5: Hạn (ngày thứ) | H5: Trạng thái
A6: 1 | B6: Trang bìa | C6: Logo, tên trường/Khoa, đề tài, GV hướng dẫn, 3 thành viên (theo sheet 'Thông tin bìa') | D6: Hữu Nam | E6: 1 | F6: Không | G6: 4 | H6: Chưa viết
A7: 2 | B7: Lời cảm ơn, nhận xét GV, mục lục, danh mục hình/bảng, từ viết tắt | C7: Theo template Khoa | D7: Kiệt | E7: 4 | F7: Không | G7: 4 | H7: Chưa viết
A8: 3 | B8: Mở đầu | C8: Lý do chọn đề tài, mục tiêu, phạm vi, bố cục báo cáo | D8: Kiệt | E8: 2 | F8: Có | G8: 1 | H8: Chưa viết
A9: 4 | B9: Chương 1. Tổng quan đề tài & phân tích yêu cầu | C9: Khảo sát CellphoneS, yêu cầu chức năng/phi chức năng, use case | D9: Kiệt | E9: 4 | F9: Có | G9: 1 | H9: Chưa viết
A10: 5 | B10: Chương 2. Cơ sở lý thuyết REST | C10: Nguyên tắc REST (client-server, stateless, cacheable, layered, uniform interface, resource representation, HATEOAS); HTTP methods GET/POST/PUT/PATCH/DELETE ↔ CRUD; safe/idempotent; status code; bảng ánh xạ endpoint TechStore | D10: Thành Trung | E10: 7 | F10: Có | G10: 2 | H10: Chưa viết
A11: 6 | B11: Chương 3. Bảo mật API & so sánh kiến trúc | C11: JWT, OAuth 2.0 (authorization code + PKCE), API key/Basic/session, HMAC webhook, OWASP API Top 10; REST vs GraphQL vs SOAP kèm số liệu thực nghiệm | D11: Hữu Nam | E11: 7 | F11: Có | G11: 2 | H11: Chưa viết
A12: 7 | B12: Chương 4. Thiết kế hệ thống | C12: Kiến trúc, ERD, thiết kế API, luồng QR, thuật toán gợi ý và đánh giá | D12: Thành Trung | E12: 9 | F12: Có | G12: 3 | H12: Chưa viết
A13: 8 | B13: Chương 5. Cài đặt, kiểm thử & demo | C13: Giao diện khách/admin, Postman, test case, kết quả | D13: Kiệt | E13: 8 | F13: Có | G13: 4 | H13: Chưa viết
A14: 9 | B14: Chương 6. Kết luận & hướng phát triển | C14: Kết quả đạt được, hạn chế, hướng phát triển | D14: Hữu Nam | E14: 2 | F14: Có | G14: 4 | H14: Chưa viết
A15: 10 | B15: Tài liệu tham khảo | C15: Theo chuẩn trích dẫn của Khoa | D15: Hữu Nam | E15: 1 | F15: Có | G15: 4 | H15: Chưa viết
A16: 11 | B16: Phụ lục | C16: ERD đầy đủ, danh sách API, test case, bảng đóng góp từng thành viên, hướng dẫn cài đặt | D16: Hữu Nam | E16: 6 | F16: Không | G16: 4 | H16: Chưa viết

Sheet Video
A1: VIDEO THUYẾT TRÌNH – KỊCH BẢN BẤM GIỜ (tối đa 20 phút)
A2: Bắt buộc: lý thuyết + kiến trúc + giải thích code + demo; cả 3 thành viên cùng thuyết trình. Ô xanh dương = số phút, có thể sửa.
B3: Tổng thời lượng (phút) | C3: =SUM(E6:E16) -> 18 | D3: =IF(C3<=20,"ĐẠT (≤ 20 phút)","VƯỢT 20 PHÚT – cắt bớt") -> ĐẠT (≤ 20 phút)
B4: Dự phòng so với 20 phút | C4: =20-C3 -> 2
A5: # | B5: Phần | C5: Nội dung | D5: Người trình bày | E5: Phút | F5: Bắt đầu (phút thứ) | G5: Loại nội dung
A6: 1 | B6: Mở đầu | C6: Giới thiệu nhóm, đề tài TechStore, bố cục video | D6: Hữu Nam | E6: 1 | F6: 0 | G6: Giới thiệu
A7: 2 | B7: Lý thuyết REST | C7: Nguyên tắc REST (stateless, uniform interface…), HTTP methods & CRUD, status code | D7: Thành Trung | E7: 2 | F7: =SUM($E$6:E6) -> 1 | G7: Lý thuyết
A8: 3 | B8: Bảo mật & so sánh | C8: JWT, OAuth 2.0; so sánh REST vs GraphQL vs SOAP (kèm số liệu thực nghiệm) | D8: Hữu Nam | E8: 2 | F8: =SUM($E$6:E7) -> 3 | G8: Lý thuyết
A9: 4 | B9: Kiến trúc hệ thống | C9: Sơ đồ Front-end ↔ REST API ↔ MySQL, Router/MVC, ERD, luồng thanh toán QR | D9: Hữu Nam | E9: 2 | F9: =SUM($E$6:E8) -> 5 | G9: Kiến trúc
A10: 5 | B10: Giải thích code – Auth, Order, QR | C10: JwtService, middleware phân quyền, tạo đơn (transaction), QrService | D10: Hữu Nam | E10: 2 | F10: =SUM($E$6:E9) -> 7 | G10: Giải thích code
A11: 6 | B11: Giải thích code – Sản phẩm & gợi ý | C11: Lọc/tìm/phân trang, cosine similarity, co-occurrence, điểm cá nhân hóa | D11: Thành Trung | E11: 2 | F11: =SUM($E$6:E10) -> 9 | G11: Giải thích code
A12: 7 | B12: Giải thích code – Front-end | C12: api.js (gắn JWT, refresh token), render động, trang QR polling | D12: Kiệt | E12: 1.5 | F12: =SUM($E$6:E11) -> 11 | G12: Giải thích code
A13: 8 | B13: Demo khách hàng | C13: Đăng ký → tìm/lọc → chi tiết + gợi ý → giỏ → thanh toán QR → theo dõi đơn | D13: Kiệt | E13: 2 | F13: =SUM($E$6:E12) -> 12.5 | G13: Demo
A14: 9 | B14: Demo quản trị | C14: Dashboard, CRUD sản phẩm, xử lý đơn, xác nhận thanh toán | D14: Kiệt | E14: 1.5 | F14: =SUM($E$6:E13) -> 14.5 | G14: Demo
A15: 10 | B15: Demo API với Postman | C15: Đăng nhập lấy JWT, gọi endpoint có/không token (401/403), token hết hạn/refresh, CRUD | D15: Thành Trung | E15: 1.5 | F15: =SUM($E$6:E14) -> 16 | G15: Demo
A16: 11 | B16: Kết luận | C16: Kết quả, hạn chế, hướng phát triển, cảm ơn | D16: Hữu Nam | E16: 0.5 | F16: =SUM($E$6:E15) -> 17.5 | G16: Kết luận
B19: Thành viên | C19: Số phút | D19: Số phần
B20: Hữu Nam | C20: =SUMIF($D$6:$D$16,B20,$E$6:$E$16) -> 7.5 | D20: =COUNTIF($D$6:$D$16,B20) -> 5
B21: Thành Trung | C21: =SUMIF($D$6:$D$16,B21,$E$6:$E$16) -> 5.5 | D21: =COUNTIF($D$6:$D$16,B21) -> 3
B22: Kiệt | C22: =SUMIF($D$6:$D$16,B22,$E$6:$E$16) -> 5 | D22: =COUNTIF($D$6:$D$16,B22) -> 3
B23: Kiểm tra thành viên | C23: =IF(AND(C20>0,C21>0,C22>0),"Cả 3 thành viên đều trình bày","THIẾU thành viên") -> Cả 3 thành viên đều trình bày
B25: YÊU CẦU KỸ THUẬT KHI QUAY
B26: Mỗi người tự quay phần của mình (hoặc họp Meet/Zoom và ghi hình) rồi dựng ghép; quay thử 1 lần trước.
B27: Âm thanh: dùng mic rời/tai nghe có mic, phòng yên tĩnh, tắt thông báo; nói chậm, rõ.
B28: Hình ảnh: độ phân giải ≥ 1080p; phóng to chữ trong IDE (≥ 16pt) và trình duyệt (Ctrl +); ẩn thông tin cá nhân/tab không liên quan.
B29: Có hình mặt hoặc tên người nói ở đầu mỗi phần để giám khảo thấy rõ cả 3 thành viên tham gia.
B30: Chạy sẵn dữ liệu demo (seed) và một bản ghi hình dự phòng cho phần demo phòng khi lỗi mạng.
B31: Xuất MP4 (H.264), kiểm tra lại toàn bộ video và thời lượng thực tế ≤ 20 phút trước khi nộp.

Sheet Thông tin bìa
A1: THÔNG TIN TRANG BÌA BÁO CÁO – KIỂM TRA CHÉO (tránh sai logo, tên GV, thành viên)
A2: Nền vàng = ô cần điền. Hàng ví dụ ở dòng 6 chỉ để minh họa – xóa khi điền thật. Mỗi mục cần 2 người kiểm tra chéo trước khi nộp.
A5: # | B5: Thông tin trên bìa | C5: Giá trị (điền) | D5: Nguồn xác nhận | E5: Người kiểm tra 1 | F5: Người kiểm tra 2 | G5: Kết quả
A6: Ví dụ | B6: Giảng viên hướng dẫn | C6: ThS. Nguyễn Văn A (VÍ DỤ – xóa dòng này) | D6: Email/Phiếu giao đề của GV | E6: Kiệt | F6: Thành Trung | G6: Đã đúng
A7: 1 | B7: Tên trường / Đại học | C7: (điền đúng theo template) | D7: Template Khoa | G7: Chưa kiểm
A8: 2 | B8: Tên Khoa | C8: (điền đúng theo template) | D8: Template Khoa | G8: Chưa kiểm
A9: 3 | B9: Logo | C9: Dùng đúng file logo chính thức trong template của Khoa (không tự tìm trên mạng) | D9: Template Khoa | G9: Chưa kiểm
A10: 4 | B10: Tên học phần / môn học | C10: (điền) | D10: Phiếu giao đề / GV | G10: Chưa kiểm
A11: 5 | B11: Tên đề tài | C11: (xác nhận với GV) – bản nháp: Xây dựng website thương mại điện tử đồ công nghệ TechStore ứng dụng RESTful API (JWT, thanh toán QR, gợi ý sản phẩm) | D11: GV hướng dẫn | G11: Chưa kiểm
A12: 6 | B12: Giảng viên hướng dẫn (họ tên đầy đủ, học hàm/học vị) | C12: (điền) | D12: GV hướng dẫn | G12: Chưa kiểm
A13: 7 | B13: Lớp / Nhóm | C13: (điền) | D13: Danh sách lớp | G13: Chưa kiểm
A14: 8 | B14: Thành viên 1 – Trưởng nhóm | C14: Hữu Nam – ghi họ tên đầy đủ đúng giấy tờ – MSSV: (điền) | D14: Thẻ sinh viên | G14: Chưa kiểm
A15: 9 | B15: Thành viên 2 | C15: Kiệt – ghi họ tên đầy đủ đúng giấy tờ – MSSV: (điền) | D15: Thẻ sinh viên | G15: Chưa kiểm
A16: 10 | B16: Thành viên 3 | C16: Thành Trung – ghi họ tên đầy đủ đúng giấy tờ – MSSV: (điền) | D16: Thẻ sinh viên | G16: Chưa kiểm
A17: 11 | B17: Học kỳ / năm học | C17: (điền) | D17: Template Khoa | G17: Chưa kiểm
A18: 12 | B18: Địa điểm, tháng/năm nộp | C18: (điền) | D18: Template Khoa | G18: Chưa kiểm

Sheet API List
A1: # | B1: Method | C1: Endpoint (/api/v1) | D1: Mô tả | E1: Quyền | F1: HTTP thành công | G1: Phụ trách | H1: Ngày thứ | I1: Trạng thái
A2: 1 | B2: POST | C2: /auth/register | D2: Đăng ký tài khoản | E2: Public | F2: 201 | G2: Hữu Nam | H2: 1 | I2: Chưa bắt đầu
A3: 2 | B3: POST | C3: /auth/login | D3: Đăng nhập, trả access + refresh token | E3: Public | F3: 200 | G3: Hữu Nam | H3: 1 | I3: Chưa bắt đầu
A4: 3 | B4: POST | C4: /auth/refresh | D4: Cấp lại access token | E4: Public | F4: 200 | G4: Hữu Nam | H4: 1 | I4: Chưa bắt đầu
A5: 4 | B5: POST | C5: /auth/logout | D5: Thu hồi refresh token | E5: Customer | F5: 204 | G5: Hữu Nam | H5: 1 | I5: Chưa bắt đầu
A6: 5 | B6: GET | C6: /auth/me | D6: Thông tin người dùng hiện tại | E6: Customer | F6: 200 | G6: Hữu Nam | H6: 1 | I6: Chưa bắt đầu
A7: 6 | B7: GET | C7: /products | D7: Danh sách + lọc/tìm/sắp xếp/phân trang | E7: Public | F7: 200 | G7: Thành Trung | H7: 1 | I7: Chưa bắt đầu
A8: 7 | B8: GET | C8: /products/{id} | D8: Chi tiết sản phẩm | E8: Public | F8: 200 | G8: Thành Trung | H8: 1 | I8: Chưa bắt đầu
A9: 8 | B9: POST | C9: /products | D9: Tạo sản phẩm (kèm upload ảnh) | E9: Admin | F9: 201 | G9: Thành Trung | H9: 2 | I9: Chưa bắt đầu
A10: 9 | B10: PUT | C10: /products/{id} | D10: Cập nhật toàn bộ sản phẩm | E10: Admin | F10: 200 | G10: Thành Trung | H10: 2 | I10: Chưa bắt đầu
A11: 10 | B11: PATCH | C11: /products/{id} | D11: Cập nhật một phần (giá, tồn kho, ẩn/hiện) | E11: Admin | F11: 200 | G11: Thành Trung | H11: 2 | I11: Chưa bắt đầu
A12: 11 | B12: DELETE | C12: /products/{id} | D12: Xóa (soft delete) sản phẩm | E12: Admin | F12: 204 | G12: Thành Trung | H12: 2 | I12: Chưa bắt đầu
A13: 12 | B13: GET | C13: /categories | D13: Danh sách danh mục | E13: Public | F13: 200 | G13: Thành Trung | H13: 1 | I13: Chưa bắt đầu
... A38: 37 | B38: POST | C38: /auth/google | D38: Đăng nhập OAuth 2.0 Google (tùy chọn) | E38: Public | F38: 200 | G38: Hữu Nam | H38: 3 | I38: Chưa bắt đầu

Sheet Rủi ro
A1: # | B1: Rủi ro | C1: Xác suất | D1: Tác động | E1: Biện pháp giảm thiểu | F1: Người phụ trách
A2: 1 | B2: Xung đột code khi nhiều người sửa file chung (routes.php, schema.sql) | C2: Cao | D2: TB | E2: Mỗi việc một nhánh feature; chia file route theo module; báo nhóm trước khi sửa file chung; rebase hằng ngày | F2: Hữu Nam
A3: 2 | B3: FE và BE lệch hợp đồng API, phải làm lại | C3: TB | D3: Cao | E3: Chốt openapi.yaml từ ngày 1; FE dùng dữ liệu mock theo OpenAPI khi BE chưa xong | F3: Hữu Nam
A4: 3 | B4: Thuật toán gợi ý không kịp/không hiệu quả do ít dữ liệu | C4: TB | D4: TB | E4: Seed ≥30 đơn mẫu; làm content-based trước (đơn giản, ổn định), co-occurrence sau; có cold-start fallback | F4: Thành Trung
A5: 4 | B5: Tích hợp QR/thanh toán phụ thuộc dịch vụ ngoài | C5: TB | D5: TB | E5: Dùng URL ảnh VietQR (không cần API key) + xác nhận thủ công/webhook giả lập; có video demo dự phòng | F5: Hữu Nam
A6: 5 | B6: Lỗ hổng bảo mật (SQLi, XSS, IDOR, lộ JWT secret) | C6: TB | D6: Cao | E6: PDO prepared statements 100%; escape output; kiểm tra quyền sở hữu tài nguyên; .env không commit; rà soát bảo mật ngày 3 (T51), sửa lỗi ngày 4 (kèm nhờ AI review theo OWASP) | F6: Hữu Nam
A7: 6 | B7: Thành viên ốm/vắng mặt, trễ tiến độ | C7: TB | D7: Cao | E7: Buffer: nửa cuối ngày 4; stand-up hằng ngày; việc quan trọng có người review đã nắm; nếu trễ làm sau cùng các việc ưu tiên TB (OAuth Google, T71, T72, T74) rồi bù ở ngày 4 | F7: Hữu Nam
A8: 7 | B8: Scope creep – thêm tính năng ngoài kế hoạch | C8: Cao | D8: TB | E8: Chỉ thêm khi xong việc 'Cao'; mọi thay đổi ghi vào Backlog và được leader duyệt | F8: Hữu Nam
A9: 8 | B9: Môi trường mỗi máy khác nhau (phiên bản PHP/MySQL) | C9: TB | D9: TB | E9: Thống nhất PHP 8.x, MySQL 8; hướng dẫn cài trong README; dùng schema.sql + seed.sql chung | F9: Kiệt
A10: 9 | B10: Essay thiếu thời gian vì dồn cuối | C10: Cao | D10: TB | E10: Dàn ý ngày 1; viết chương lý thuyết sớm (ngày 1–2), các chương còn lại ngay khi xong phần code tương ứng (ngày 3–4) nhờ AI soạn nháp rồi tự sửa; cuối ngày 4 chỉ hiệu đính | F10: Kiệt
A11: 10 | B11: Báo cáo sai thông tin bìa (logo, tên GV, thành viên) hoặc không bám template Khoa | C11: TB | D11: Cao | E11: Xác nhận thông tin bìa với GV ngày 1; điền sheet 'Thông tin bìa'; kiểm tra chéo bởi ≥ 2 người trên cả Word và PDF | F11: Hữu Nam
A12: 11 | B12: Báo cáo ngoài khoảng 20–60 trang (không tính bìa & phụ lục) | C12: TB | D12: TB | E12: Theo bảng phân bổ trang (sheet 'Báo cáo'); kiểm tra số trang khi ghép; chuyển phần thừa vào phụ lục | F12: Hữu Nam
A13: 12 | B13: Video vượt 20 phút, thiếu thành viên hoặc âm thanh/hình ảnh kém | C13: TB | D13: Cao | E13: Kịch bản bấm giờ (sheet 'Video'); quay thử; mic rời, phòng yên tĩnh; kiểm tra toàn bộ video trước khi nộp | F13: Thành Trung
... A16: 15 | B16: 4 ngày quá gấp: khối lượng ~8,5–9,5 giờ/người/ngày, việc báo cáo/video dồn về ngày 3–4 | C16: Cao | D16: Cao | E16: Viết chương lý thuyết ngay ngày 1–2; chốt kịch bản video ngày 3; feature freeze cuối ngày 3; code freeze trưa ngày 4; việc ưu tiên TB làm sau cùng; stand-up đầu ngày để chia lại việc | F16: Hữu Nam

Sheet Chuẩn DoD
A1: DEFINITION OF DONE – một nhiệm vụ chỉ được 'Hoàn thành' khi:
A2: ☐ | B2: Code chạy được trên local, không lỗi PHP (error_log) và không lỗi console JS
A3: ☐ | B3: Đã test endpoint/giao diện bằng Postman hoặc thao tác thật, kèm test case thành công + thất bại
A4: ☐ | B4: Đã mở Pull Request vào develop, có ≥1 người review và đã xử lý comment
A5: ☐ | B5: Tuân thủ chuẩn code (PSR-12, đặt tên rõ nghĩa), không còn code debug/var_dump
A6: ☐ | B6: Validate input phía server, dùng PDO prepared statements, kiểm tra quyền (role/owner)
A7: ☐ | B7: Cập nhật openapi.yaml / Postman collection nếu thay đổi API
A8: ☐ | B8: Không commit .env, mật khẩu, file upload, vendor không cần thiết
A9: ☐ | B9: Cập nhật trạng thái & % hoàn thành trong sheet 'Phân công'
A11: DEFINITION OF READY – một nhiệm vụ chỉ bắt đầu khi:
A12: ☐ | B12: Mô tả và sản phẩm bàn giao rõ ràng; có người phụ trách và người review
A13: ☐ | B13: Các nhiệm vụ phụ thuộc đã xong hoặc đã có mock/hợp đồng API
A14: ☐ | B14: Có nhánh Git riêng theo quy ước feature/<tên-việc>
A16: NGHI THỨC LÀM VIỆC
A17: ☐ | B17: Stand-up 15 phút lúc 08:30: hôm qua – hôm nay – vướng mắc (nhắn nhóm nếu không họp được)
A18: ☐ | B18: Cuối ngày 17:30: cập nhật bảng phân công, merge PR đã duyệt, leader kiểm tra develop chạy ổn
A19: ☐ | B19: Checkpoint 1 vào cuối ngày 2 (~50%) và Checkpoint 2 (feature freeze) cuối ngày 3
A20: ☐ | B20: Ngày 4 buổi sáng: chỉ test, sửa lỗi, rà bảo mật – không thêm tính năng mới
A21: ☐ | B21: Ngày 4 trưa: code freeze, tag v1.0.0; chiều: hoàn thiện báo cáo, quay video, đóng gói nộp bài
A23: TÀI LIỆU CẦN CÓ KHI NỘP
A24: ☐ | B24: Readme.md (yêu cầu hệ thống, cài đặt từng bước, tài khoản admin) · GIT_WORKFLOW.md
A25: ☐ | B25: docs/erd.png, database/schema.sql, database/seed.sql
A26: ☐ | B26: docs/openapi.yaml và Postman collection + environment
A27: ☐ | B27: Báo cáo Word + PDF: 20–60 trang (không tính bìa & phụ lục), đúng template Khoa, bìa chính xác (logo, tên GV, 3 thành viên)
A28: ☐ | B28: Video thuyết trình ≤ 20 phút (đủ 3 thành viên) · Source code kèm file thư viện · Readme.md có tài khoản admin
A30: QUY TẮC VIBE CODING (làm việc với AI)
A31: ☐ | B31: Mọi prompt đều dán CONTEXT.md (stack, quy ước, định dạng JSON) + phần openapi.yaml / schema.sql liên quan
A32: ☐ | B32: Chia nhỏ yêu cầu: mỗi lần 1 endpoint hoặc 1 trang; chạy thử ngay, có lỗi thì dán nguyên log cho AI
A33: ☐ | B33: Không merge code chưa chạy thử; mỗi nhánh feature chỉ chứa một việc
A34: ☐ | B34: Mỗi người đọc hiểu và giải thích được code phần mình (sẽ phải nói trong video)
A35: ☐ | B35: Luôn yêu cầu AI dùng PDO prepared statements, kiểm tra quyền sở hữu (chống IDOR), không hardcode secret
A36: ☐ | B36: Không dán mật khẩu / khóa thật (.env) cho AI
